Workbook

Sheet Read Me
A1: Configuration Copilot: Golden Data Set
A2: Vertex Ops case study · synthetic data · all customers, people and values are fictional
A4: Purpose | B4: The answer key used to design and test the Configuration Copilot. Each sheet pairs realistic inputs with the output the system is expected to produce, so every layer (rules, fast decision layer, LLM agents) can be scored before launch and after every change.
A5: Domain (A0) | B5: Mid-market Indian companies running order-to-delivery operations: distributors, D2C brands and 3PLs. Modules: Order Management, Fulfilment & Allocation, Shipping & Delivery, plus Admin & Access.
A6: How to read | B6: Dark navy headers = inputs the system receives. Teal headers with tinted cells = the answer key (expected output). Score the system by comparing its output with the answer key.
A7: Layers | B7: R = rules/automation · J = fast decision layer (Jev candidate, shadow mode in MVP) · L = LLM agent · H = human decision.
A8: Difficulty | B8: Easy = single clear signal · Medium = needs one inference · Hard = traps: contradictions, two causes, noise that looks like drift, cases where the right answer is 'do nothing' or 'ask the customer'.
A9: Sheet guide
A10: Summary | B10: Live case counts and mix (formulas).
A11: Customers | B11: 21 synthetic customers across Sales (8), UAT (5) and Production (8).
A12: Template | B12: Logistics template built on the domain-neutral base schema: thresholds (THR), rules (RULE), workflows (WF), integrations (INT), admin (ADM).
A13: Metrics & Health | B13: UAT metric checklist (M1-M10 performance and load, C1-C4 correctness) and production health checks (H1-H13).
A14: S1 Clarification | B14: MVP · Sales · Requirement Clarification Agent (L): ambiguity detection, follow-up questions, sign-off values.
A15: S2 Config Checks | B15: MVP · Sales · rule-based checks (R) on draft configurations against signed-off values.
A16: U1 UAT Diagnosis | B16: MVP · UAT · Diagnosis & Tuning Agent (R narrows, J ranks, L investigates): root cause, cause class, expected action.
A17: P1 Safety Net (MVP) | B17: MVP · Production · rule-based H1/H3/H4 checks with escalation. No AI touches live customers.
A18: P2 Drift (V2) | B18: V2 · Production · Level 2 fit monitoring: real drift vs noise vs sustained growth.
A19: Evaluation | B19: How each sheet is scored and the proposed launch gates.
A20: Assumptions | B20: Assumption register A0-A20 referenced across the submission.
A21: Data handling | B21: Consistent with A18: cases use configuration, aggregated metrics and event patterns only. No consumer personal data appears anywhere in this file.
... A23: Prioritisation | B23: Weighted scoring used to choose the MVP scope.

Sheet Summary
A1: Summary
A2: All counts below are live formulas over the case sheets.
A5: Cases by sheet
A6: S1 Clarification (MVP, Sales, L) | B6: =COUNTA('S1 Clarification'!$A$5:$A$32) -> 28 | C6: Agent must flag, question and resolve
A7: S2 Config Checks (MVP, Sales, R) | B7: =COUNTA('S2 Config Checks'!$A$5:$A$24) -> 20 | C7: Deterministic rule checks
A8: U1 UAT Diagnosis (MVP, UAT, R+J+L) | B8: =COUNTA('U1 UAT Diagnosis'!$A$5:$A$16) -> 12 | C8: Root cause and action
A9: P1 Safety Net (MVP, Production, R) | B9: =COUNTA('P1 Safety Net (MVP)'!$A$5:$A$14) -> 10 | C9: Hard-failure rules
A10: P2 Drift (V2, Production, R+J+L) | B10: =COUNTA('P2 Drift (V2)'!$A$5:$A$12) -> 8 | C10: Drift vs noise
A11: Total cases | B11: =SUM(B6:B10) -> 78
A13: S1 mix
A14: Should be flagged (ambiguous) | B14: =COUNTIF('S1 Clarification'!$F$5:$F$32,"Yes") -> 22 | C14: Tests recall
A15: Controls: must NOT be flagged | B15: =COUNTIF('S1 Clarification'!$F$5:$F$32,"No") -> 4 | C15: Tests false flags
A16: Out of scope: route to SE | B16: =COUNTIF('S1 Clarification'!$F$5:$F$32,"Route to SE") -> 2 | C16: Tests 'do not invent settings'
A17: Contradictions | B17: =COUNTIF('S1 Clarification'!$E$5:$E$32,"Contradiction") -> 2
A19: S2 mix
A20: Errors (block handoff) | B20: =COUNTIF('S2 Config Checks'!$G$5:$G$24,"Error") -> 11
A21: Warnings (do not block) | B21: =COUNTIF('S2 Config Checks'!$G$5:$G$24,"Warning") -> 4
A22: Pass | B22: =COUNTIF('S2 Config Checks'!$G$5:$G$24,"Pass") -> 5 | C22: Tests false blocks
A24: U1 mix
A25: Configuration errors (incl. two-cause, capacity) | B25: =COUNTIF('U1 UAT Diagnosis'!$I$5:$I$16,"Configuration error*") -> 7
A26: Requirement conflicts with target (ask customer) | B26: =COUNTIF('U1 UAT Diagnosis'!$I$5:$I$16,"Requirement conflicts with target") -> 2 | C26: Agent must escalate, not fix
A27: Test data issue (no change) | B27: =COUNTIF('U1 UAT Diagnosis'!$I$5:$I$16,"Test data issue") -> 1 | C27: Correct answer is 'do nothing'
A28: Rule-only (AI not invoked) | B28: =COUNTIF('U1 UAT Diagnosis'!$I$5:$I$16,"Rule-only*") -> 1
A29: Regression from recent change | B29: =COUNTIF('U1 UAT Diagnosis'!$I$5:$I$16,"Regression*") -> 1
A31: P1 / P2 mix
A32: Safety net: alert expected | B32: =COUNTIF('P1 Safety Net (MVP)'!$E$5:$E$14,"Yes*") -> 6
A33: Safety net: near misses (no alert) | B33: =COUNTIF('P1 Safety Net (MVP)'!$E$5:$E$14,"No") -> 4 | C33: Tests false alarms
A34: Drift: real drift | B34: =COUNTIF('P2 Drift (V2)'!$P$5:$P$12,"Real drift*") -> 5
A35: Drift: noise / sustained growth | B35: =COUNTA('P2 Drift (V2)'!$P$5:$P$12)-B34 -> 3 | C35: Must not raise a drift alert
A37: Difficulty (all agent sheets: S1, U1, P2)
A38: Hard | B38: =COUNTIF('S1 Clarification'!$M$5:$M$32,"Hard")+COUNTIF('U1 UAT Diagnosis'!$M$5:$M$16,"Hard")+COUNTIF('P2 Drift (V2)'!$T$5:$T$12,"Hard") -> 14
A39: Medium | B39: =COUNTIF('S1 Clarification'!$M$5:$M$32,"Medium")+COUNTIF('U1 UAT Diagnosis'!$M$5:$M$16,"Medium")+COUNTIF('P2 Drift (V2)'!$T$5:$T$12,"Medium") -> 16
A40: Easy | B40: =COUNTIF('S1 Clarification'!$M$5:$M$32,"Easy")+COUNTIF('U1 UAT Diagnosis'!$M$5:$M$16,"Easy")+COUNTIF('P2 Drift (V2)'!$T$5:$T$12,"Easy") -> 10

Sheet Business Case
A1: Business case: assumptions F1-F21, formulas, base and conservative cases
A2: Blue cells on yellow are inputs: replace with Vertex Ops actuals and every output recalculates. The codes match the deck footnotes.
A4: Code | B4: Input | C4: Value | D4: Unit | E4: Type | F4: Basis
A5: F1 | B5: Customers in UAT at any time | C5: 5 | D5: customers | E5: Case fact | F5: Case: ~5 customers in UAT
A6: F2 | B6: Average UAT duration | C6: 4 | D6: weeks | E6: Assumption | F6: Typical mid-market SaaS UAT window of 3-6 weeks
A7: F3 | B7: Customers in sales configuration at any time | C7: 10 | D7: customers | E7: Case fact | F7: Case: ~10 customers in sales
A8: F4 | B8: UAT test cycles per customer today | C8: 4 | D8: cycles | E8: Assumption | F8: Weekly retest across a 4-week UAT
A9: F5 | B9: UAT test cycles per customer with the Copilot | C9: 2 | D9: cycles | E9: Pilot hypothesis | F9: One cycle to find issues, one to confirm; conservative case uses 3
A10: F6 | B10: Delivery hours per UAT cycle | C10: 30 | D10: hours | E10: Assumption | F10: Test, diagnose and fix effort across delivery specialists per cycle
A11: F7 | B11: SE rework hours saved per customer | C11: 10 | D11: hours | E11: Assumption | F11: Reconfiguring settings sent back from UAT; conservative case uses 5
A12: F8 | B12: Loaded cost per specialist / engineer hour | C12: 2500 | D12: INR | E12: Assumption | F12: ~₹45 L a year fully loaded ÷ 1,800 productive hours
A13: F9 | B13: Productive hours per FTE per year | C13: 1800 | D13: hours | E13: Assumption | F13: Standard planning figure after leave and overheads
A14: F10 | B14: Average annual contract value (mid-market) | C14: 3000000 | D14: INR | E14: Assumption | F14: Mid-market B2B SaaS contract
A15: F11 | B15: Live production accounts | C15: 300 | D15: accounts | E15: Assumption | F15: Mid-point reading of the case's 'hundreds'
A16: F12 | B16: MVP team size | C16: 5 | D16: FTE | E16: Assumption | F16: 1 PM, 3 engineers, 1 AI engineer (roadmap)
... A27: F21 | B27: Fast-decision-layer price | C27: 4 | D27: INR per million tokens | E27: Assumption | F27: ~US$0.042 per M input tokens reported by an early Jev user, rounded up
A29: Outputs: base case (formulas)
B30: Output | C30: Value | D30: Unit | E30: Calculation (codes)
B31: Go-lives per year | C31: =$C$5/$C$6*52 -> 65 | D31: customers/yr | E31: F1 ÷ F2 × 52 (Little's law)
B32: Implied weeks in sales configuration | C32: =$C$7/C31*52 -> 8 | D32: weeks | E32: F3 ÷ go-lives × 52
B33: Delivery hours in UAT today | C33: =C31*$C$8*$C$10 -> 7800 | D33: hours/yr | E33: Go-lives × F4 × F6
B34: Hours saved per customer | C34: =($C$8-$C$9)*$C$10+$C$11 -> 70 | D34: hours | E34: (F4 − F5) × F6 + F7
B35: Specialist capacity freed | C35: =C31*C34 -> 4550 | D35: hours/yr | E35: Go-lives × hours saved per customer
B36: FTE equivalent | C36: =C35/$C$13 -> 2.5277778 | D36: FTE | E36: Hours freed ÷ F9
B37: Value of capacity freed | C37: =C35*$C$12 -> 11375000 | D37: INR/yr | E37: Hours freed × F8
B38: Weeks per UAT cycle | C38: =$C$6/$C$8 -> 1 | D38: weeks | E38: F2 ÷ F4
B39: Go-live brought forward per customer | C39: =($C$8-$C$9)*C38 -> 2 | D39: weeks | E39: (F4 − F5) × weeks per cycle
B40: Revenue recognised earlier | C40: =C31*$C$14*C39/52 -> 7500000 | D40: INR/yr | E40: Go-lives × F10 × weeks earlier ÷ 52 (timing, not new revenue)
B41: Annual contract value running unmonitored | C41: =$C$15*$C$14 -> 900000000 | D41: INR | E41: F11 × F10
B42: MVP cost to go-live | C42: =$C$16*$C$17*$C$18*$C$12 -> 12000000 | D42: INR | E42: F12 team × weeks × hours × F8
B43: Payback on capacity value | C43: =C42/C37*12 -> 12.659341 | D43: months | E43: MVP cost ÷ annual capacity value × 12
B44: AI model run cost | C44: =C31*$C$20*$C$21 -> 113750 | D44: INR/yr | E44: Go-lives × F14 × F15
B45: Client staff hours spent in UAT | C45: =C31*$C$8*$C$19 -> 3120 | D45: hours/yr | E45: Go-lives × F4 × F13 (cost to the end user)
B46: Client staff hours saved | C46: =C31*($C$8-$C$9)*$C$19 -> 1560 | D46: hours/yr | E46: Go-lives × (F4 − F5) × F13
B47: Customer-weeks of waiting removed | C47: =C31*C39 -> 130 | D47: weeks/yr | E47: Go-lives × weeks brought forward
B48: Deviations triaged a year (V2) | C48: =$C$15*$C$23*52 -> 78000 | D48: deviations/yr | E48: F11 × F17 × 52
B49: V2 model cost, LLM investigates every deviation | C49: =C48*$C$25*$C$21 -> 1950000 | D49: INR/yr | E49: Deviations × F19 × F15
B50: V2 model cost, fast decision layer triages first | C50: =C48*$C$26*$C$27+C48*$C$24*$C$25*$C$21 -> 195624 | D50: INR/yr | E50: Deviations × F20 × F21 + deviations × F18 × F19 × F15
B51: V2 model cost avoided by triage | C51: =C49-C50 -> 1754376 | D51: INR/yr | E51: LLM-only − triage-first
B52: Annual run cost (MVP) | C52: =C44+$C$22 -> 713750 | D52: INR/yr | E52: AI model run cost + F16
...

Sheet Prioritisation
A1: Where to start: weighted prioritisation
A2: Ratings 1 (worst) to 5 (best) are our assessment from the as-is analysis. Change weights or ratings and the scores recalculate.
A4: Criterion | B4: Cost of the problem | C4: Frequency | D4: Feasibility (small team, existing APIs) | E4: Safety for live customers | F4: Speed to prove value | G4: Total
A5: Weight | B5: 0.25 | C5: 0.15 | D5: 0.2 | E5: 0.2 | F5: 0.2 | G5: =SUM(B5:F5) -> 1
A7: Opportunity | B7: Cost of the problem | C7: Frequency | D7: Feasibility (small team, existing APIs) | E7: Safety for live customers | F7: Speed to prove value | G7: Weighted score | H7: Decision
A8: A. Sales: requirement clarification + configuration checks | B8: 4 | C8: 5 | D8: 4 | E8: 5 | F8: 4 | G8: =SUMPRODUCT($B$5:$F$5,B8:F8) -> 4.35 | H8: MVP
A9: B. UAT: diagnosis and tuning | B9: 5 | C9: 4 | D9: 3 | E9: 5 | F9: 5 | G9: =SUMPRODUCT($B$5:$F$5,B9:F9) -> 4.45 | H9: MVP
A10: C. Production: AI fit and drift monitoring | B10: 4 | C10: 3 | D10: 3 | E10: 2 | F10: 2 | G10: =SUMPRODUCT($B$5:$F$5,B10:F10) -> 2.85 | H10: V2
A11: D. Production: rule-based safety net (H1, H3, H4) | B11: 3 | C11: 3 | D11: 5 | E11: 5 | F11: 4 | G11: =SUMPRODUCT($B$5:$F$5,B11:F11) -> 4 | H11: MVP

Sheet Customers
A1: Synthetic customers
A2: Volumes are orders per day. Peak multiplier and peak calendar feed the capacity envelope (M7-M10, A14).
A4: ID | B4: Customer (fictional) | C4: Segment | D4: City | E4: Normal orders/day | F4: Peak multiplier | G4: Known peaks | H4: Warehouses | I4: Order source | J4: Carriers | K4: Stage | L4: Live since
A5: C01 | B5: Aravali Agro Distributors | C5: Distributor | D5: Jaipur | E5: 900 | F5: 2.2 | G5: Rabi & Kharif sowing seasons | H5: 3 | I5: ERP | J5: 2 courier + 1 freight | K5: Sales
A6: C02 | B6: Kesar Naturals | C6: D2C brand | D6: Pune | E6: 1500 | F6: 3 | G6: Diwali, year-end sale | H6: 2 | I6: Web store | J6: 2 courier + 1 freight | K6: Sales
A7: C03 | B7: Konark Auto Spares | C7: Distributor | D7: Bhubaneswar | E7: 1200 | F7: 2.9 | G7: Diwali | H7: 2 | I7: ERP | J7: 2 courier + 1 freight | K7: Sales
A8: C04 | B8: Meghdoot 3PL Services | C8: 3PL | D8: Nagpur | E8: 4000 | F8: 2.5 | G8: Diwali, month-end | H8: 4 | I8: 4 client systems | J8: 3 courier + 1 freight | K8: Sales
A9: C05 | B9: Tanvi Fashion House | C9: D2C brand | D9: Surat | E9: 2200 | F9: 3.5 | G9: Diwali, wedding season, EOSS | H9: 1 | I9: Web store | J9: 2 courier | K9: Sales
A10: C06 | B10: Sahyadri FMCG Distributors | C10: Distributor | D10: Nashik | E10: 2600 | F10: 1.8 | G10: Month-end, Diwali | H10: 3 | I10: ERP | J10: 1 courier + 2 freight | K10: Sales
A11: C07 | B11: Vindhya Electricals | C11: Distributor | D11: Indore | E11: 700 | F11: 2 | G11: Summer (Apr-Jun) | H11: 2 | I11: ERP | J11: 1 courier + 1 freight | K11: Sales
A12: C08 | B12: Nilgiri Home Essentials | C12: D2C brand | D12: Coimbatore | E12: 1100 | F12: 2.8 | G12: Diwali, Pongal | H12: 1 | I12: Web store | J12: 2 courier | K12: Sales
A13: C09 | B13: Ganga Steel Traders | C13: Distributor | D13: Kanpur | E13: 450 | F13: 1.6 | G13: Quarter-end | H13: 2 | I13: ERP | J13: 2 freight | K13: UAT
A14: C10 | B14: Rangoli Home Decor | C14: D2C brand | D14: Jaipur | E14: 1300 | F14: 3.2 | G14: Diwali | H14: 2 | I14: Web store | J14: 2 courier + 1 freight | K14: UAT
A15: C11 | B15: Kaveri Kitchenware | C15: D2C brand | D15: Bengaluru | E15: 1800 | F15: 2.7 | G15: Diwali, Onam | H15: 2 | I15: Web store | J15: 2 courier | K15: UAT
A16: C12 | B16: Deccan Link 3PL | C16: 3PL | D16: Hyderabad | E16: 5200 | F16: 3 | G16: Diwali, month-end | H16: 3 | I16: 3 client systems | J16: 3 courier + 1 freight | K16: UAT
A17: C13 | B17: Pavitra Organics | C17: D2C brand | D17: Dehradun | E17: 600 | F17: 2.4 | G17: Diwali | H17: 1 | I17: Web store | J17: 2 courier | K17: UAT
A18: C14 | B18: Shakti Industrial Supplies | C18: Distributor | D18: Ludhiana | E18: 1000 | F18: 1.7 | G18: Quarter-end | H18: 2 | I18: ERP | J18: 1 courier + 2 freight | K18: Production | L18: Jan 2026
A19: C15 | B19: Utsav Gifting Co. | C19: D2C brand | D19: Delhi | E19: 2400 | F19: 3.8 | G19: Diwali, Rakhi, year-end | H19: 2 | I19: Web store | J19: 3 courier | K19: Production | L19: Mar 2026
A20: C16 | B20: Narmada Agri Inputs | C20: Distributor | D20: Vadodara | E20: 1400 | F20: 2.3 | G20: Sowing seasons | H20: 3 | I20: ERP | J20: 2 courier + 1 freight | K20: Production | L20: Nov 2025
A21: C17 | B21: Brahmaputra Tea Traders | C21: Distributor | D21: Guwahati | E21: 800 | F21: 1.9 | G21: Flush seasons | H21: 2 | I21: ERP | J21: 2 courier + 1 freight | K21: Production | L21: Feb 2026
A22: C18 | B22: Lotus Living Furniture | C22: D2C brand | D22: Kochi | E22: 500 | F22: 2.6 | G22: Onam, Diwali | H22: 2 | I22: Web store | J22: 1 courier + 2 freight | K22: Production | L22: Dec 2025
A23: C19 | B23: Swift Basket Grocers | C23: D2C brand | D23: Mumbai | E23: 6000 | F23: 1.5 | G23: Festive weekends | H23: 4 | I23: Web store | J23: 3 courier | K23: Production | L23: Oct 2025
A24: C20 | B24: Chambal Cement Dealers | C24: Distributor | D24: Kota | E24: 650 | F24: 1.4 | G24: Month-end | H24: 2 | I24: ERP | J24: 2 freight | K24: Production | L24: Apr 2026
A25: C21 | B25: Marina Link 3PL | C25: 3PL | D25: Chennai | E25: 4500 | F25: 2.8 | G25: Diwali, Pongal, month-end | H25: 3 | I25: 5 client systems | J25: 3 courier + 1 freight | K25: Production | L25: Sep 2025

Sheet Template
A1: Logistics template (on the domain-neutral base schema)
A2: Client configuration = this template + the client's signed-off modifications. The Copilot never changes the base schema.
A4: Module | B4: ID | C4: Block | D4: Setting / logic | E4: Template default | F4: Unit | G4: Used by | H4: Metrics affected
A5: Order Management | B5: THR-01 | C5: Threshold | D5: credit_limit (per buyer) | E5: 10,00,000 | F5: INR | G5: RULE-02 | H5: M1, M3
A6: Order Management | B6: THR-03 | C6: Threshold | D6: approval_limit | E6: 5,00,000 | F6: INR | G6: RULE-12 | H6: M1, M10
A7: Order Management | B7: THR-05 | C7: Threshold | D7: approval_sla | E7: 4 | F7: business hours | G7: WF-02 / S3 | H7: M1
A8: Order Management | B8: RULE-02 | C8: Rule | D8: credit_hold: buyer outstanding + order value > THR-01 -> hold, route to WF-03 | E8: enabled | G8: WF-03 | H8: M1, M3
A9: Order Management | B9: RULE-12 | C9: Rule | D9: high_value_approval: order value > THR-03 -> route to WF-02 | E9: enabled | G9: WF-02 | H9: M1, M10
A10: Order Management | B10: WF-02 | C10: Workflow | D10: High-value approval: S1 validate > S2 stock check > S3 finance approval > S4 release | E10: S3 role = finance_approver | G10: THR-05 | H10: M1, M10
A11: Order Management | B11: WF-03 | C11: Workflow | D11: Credit hold release: S1 hold > S2 credit review | E11: S2 role = credit_controller | H11: M1
A12: Order Management | B12: INT-01 | C12: Integration | D12: Order inbound (ERP / web store) | E12: API v3, sync 15 min, 3 retries | G12: RULE-02, RULE-12 | H12: M6, C3
A13: Fulfilment & Allocation | B13: RULE-21 | C13: Rule | D13: routing: pincode region -> warehouse (specific before general) | E13: region map | G13: WF-04 | H13: M2, M3
A14: Fulfilment & Allocation | B14: RULE-22 | C14: Rule | D14: stock_out_fallback -> backup warehouse | E14: none (must set) | G14: WF-04 | H14: M2
A15: Fulfilment & Allocation | B15: THR-07 | C15: Threshold | D15: allocation_timeout | E15: 30 | F15: minutes | G15: WF-04 | H15: M2, M10
A16: Fulfilment & Allocation | B16: WF-04 | C16: Workflow | D16: Allocation & exceptions: S1 auto-allocate > S2 exception queue | E16: S2 role = warehouse_planner | G16: THR-07 | H16: M3, M10
A17: Fulfilment & Allocation | B17: INT-02 | C17: Integration | D17: Warehouse system: stock & allocation | E17: API v2, sync 10 min, 3 retries | G17: RULE-21, RULE-22 | H17: M2, M6
A18: Shipping & Delivery | B18: THR-09 | C18: Threshold | D18: dispatch_sla | E18: 24 | F18: business hours | G18: WF-05, RULE-31 | H18: M4, M5
A19: Shipping & Delivery | B19: THR-10 | C19: Threshold | D19: escalation_after_sla | E19: 6 | F19: hours | G19: RULE-31 | H19: M5
A20: Shipping & Delivery | B20: THR-11 | C20: Threshold | D20: bulky_weight | E20: 100 | F20: kg | G20: RULE-32 | H20: M4
A21: Shipping & Delivery | B21: THR-13 | C21: Threshold | D21: dispatch_cutoff_time | E21: 16:00 | F21: time | G21: WF-05, RULE-31 | H21: M4, M5
A22: Shipping & Delivery | B22: RULE-31 | C22: Rule | D22: late_escalation: not dispatched by THR-09 + THR-10 -> escalate to dispatch_lead | E22: enabled | H22: M5
A23: Shipping & Delivery | B23: RULE-32 | C23: Rule | D23: carrier_selection: weight > THR-11 -> freight; else courier by zone | E23: enabled | G23: WF-05 | H23: M3, M4
A24: Shipping & Delivery | B24: WF-05 | C24: Workflow | D24: Dispatch: S1 pick-pack > S2 carrier booking > S3 handover | E24: S3 role = dispatch_lead | G24: THR-09 | H24: M4, M10
A25: Shipping & Delivery | B25: INT-03 | C25: Integration | D25: Carrier booking & tracking | E25: API v2, sync 5 min, 3 retries, rate limit 600 calls/hr | G25: RULE-32, WF-05 | H25: M6, M9
A26: Admin & Access | B26: ADM-01 | C26: Setting | D26: business_calendar | E26: Mon-Sat, 09:00-18:00 | G26: THR-05, THR-09 | H26: M1, M4
A27: Admin & Access | B27: ADM-02 | C27: Setting | D27: roles: finance_approver, credit_controller, warehouse_planner, dispatch_lead | E27: >= 1 active user each | G27: WF-02..05 | H27: C4

Sheet Metrics & Health
A1: UAT metric checklist and production health checks
A2: Targets are template defaults; each customer's targets are agreed and signed off. M1-M10 values at go-live become the production baseline.
A4: ID | B4: Type | C4: Metric | D4: Module | E4: Definition | F4: Default target | G4: Event source (A3) | H4: Settings it depends on
A5: M1 | B5: Performance (carried to production) | C5: Approval cycle time | D5: Order Mgmt | E5: Median time from approval request to decision | F5: <= 4 business hours | G5: step_completed (WF-02/S3) | H5: THR-03, THR-05, WF-02
A6: M2 | B6: Performance (carried to production) | C6: Auto-routing accuracy | D6: Fulfilment | E6: % orders allocated to the correct warehouse with no manual reassignment | F6: >= 95% | G6: rule_fired, manual_override | H6: RULE-21, RULE-22, INT-02
A7: M3 | B7: Performance (carried to production) | C7: Manual override rate | D7: All | E7: % orders where a user bypassed a rule or step | F7: <= 5% | G7: manual_override | H7: Any rule
A8: M4 | B8: Performance (carried to production) | C8: On-time dispatch | D8: Shipping | E8: % orders dispatched within dispatch SLA | F8: >= 95% | G8: step_completed (WF-05) | H8: THR-09, THR-11, THR-13, RULE-32, WF-05
A9: M5 | B9: Performance (carried to production) | C9: Escalation rate | D9: Shipping | E9: % orders that triggered a late escalation | F9: <= 3% | G9: rule_fired (RULE-31) | H9: THR-10, RULE-31, THR-13
A10: M6 | B10: Performance (carried to production) | C10: Integration sync success & delay | D10: All | E10: % successful syncs; p95 sync delay | F10: >= 99%; <= 15 min | G10: integration_sync | H10: INT-01, INT-02, INT-03
A11: M7 | B11: Load & capacity (carried to production) | C11: Concurrent users | D11: Platform | E11: p95 response time at 1.5x expected peak logged-in users | F11: <= 2 s | G11: load test / platform telemetry | H11: (platform)
A12: M8 | B12: Load & capacity (carried to production) | C12: Order throughput | D12: All | E12: Orders/hour processed without backlog at expected peak x festive multiplier | F12: No backlog at peak | G12: load test / step_completed | H12: THR-07, WF-04, WF-05
A13: M9 | B13: Load & capacity (carried to production) | C13: Integration load | D13: All | E13: Rate-limit errors from ERP / warehouse / carrier at peak volume | F13: Zero | G13: integration_sync | H13: INT-01..03
A14: M10 | B14: Load & capacity (carried to production) | C14: Workflow capacity | D14: All | E14: Approval and exception queues per assigned person clear within SLA at peak | F14: Within SLA at peak | G14: step_completed | H14: THR-03, THR-07, WF-02, WF-04
A15: C1 | B15: Correctness (one-time, go-live) | C15: End-to-end scenarios | D15: All | E15: Agreed scenarios complete correctly (normal, high-value, stock-out, late shipment, carrier failure) | F15: 100% critical; >= 95% overall | G15: UAT scenario runs | H15: All
... A18: C4 | B18: Correctness (one-time, go-live) | C18: Role completeness | D18: Admin | E18: Every workflow step has an active user in its assigned role | F18: 100% | G18: ADM-02 | H18: ADM-02
A20: Production health checks (rule-based)
A21: ID | B21: Check | C21: Rule | D21: Severity | E21: Routed to | F21: Phase
A22: H1 | B22: Integration failing | C22: Sync success < 95% over 1 hour, or authentication errors | D22: P1 | E22: Support -> Platform eng. (customer-side: CSM -> customer IT) | F22: MVP
A23: H2 | B23: Integration slow | C23: p95 sync delay > 2x target for 2 hours | D23: P2 | E23: Support -> Platform eng. | F23: V2
A24: H3 | B24: Orders stuck | C24: Orders in a workflow step > 2x its SLA | D24: P2 | E24: CSM -> customer admin | F24: MVP
A25: H4 | B25: Approver missing | C25: An approval step's role has no active user | D25: P1 | E25: CSM -> customer admin | F25: MVP
A26: H5 | B26: Rule never fires | C26: A normally-firing rule has not fired for 7 days | D26: P3 | E26: Config specialist (delivery) | F26: V2
A27: H6 | B27: Rule firing spike | C27: A rule fires > 3x its normal rate | D27: P2 | E27: Config specialist (delivery) | F27: V2
A28: H7 | B28: Data rejections | C28: Orders rejected for missing/invalid fields > 2% in a day | D28: P2 | E28: Config specialist (delivery) | F28: V2
A29: H8 | B29: Metric breach | C29: Any of M1-M6 below target for 3 consecutive days | D29: P2 | E29: CSM -> Level 2 fit review | F29: V2
A30: H9 | B30: Approaching capacity | C30: Load > 80% of tested capacity envelope (M7-M10) | D30: P3 | E30: CSM + Platform eng. | F30: V2
A31: H10 | B31: Exceeding capacity | C31: Load > 100% of tested capacity envelope | D31: P2 | E31: Platform eng. + CSM | F31: V2
A32: H11 | B32: Slow responses | C32: p95 response time > 2x target | D32: P1 | E32: Platform eng. | F32: V2
... A34: H13 | B34: Workflow queue overload | C34: Approval or exception queue above capacity | D34: P2 | E34: CSM -> customer admin | F34: V2

Sheet S1 Clarification
A1: MVP · Sales · Requirement Clarification Agent
A2: Ambiguity is judged against the schema: a requirement is ambiguous if it does not give a concrete value for the setting it maps to.
A4: Case | B4: Customer | C4: Handoff note (input) | D4: Linked setting(s) | E4: Ambiguity type | F4: Flag? | G4: Expected question (gist) | H4: Default offered | I4: Priority | J4: Simulated customer answer | K4: Expected resolved value | L4: Expected final status | M4: Difficulty | N4: What it tests
A5: SC-01 | B5: C01 | C5: Big orders need finance sign-off before release. | D5: THR-03, WF-02/S3 | E5: Vague quantity | F5: Yes | G5: Above what order value should finance approval be required? | H5: INR 5,00,000 | I5: High | J5: Anything above 8 lakh. | K5: THR-03 = INR 8,00,000; S3 role = finance_approver | L5: Confirmed | M5: Easy | N5: Vague amount resolved to a number
A6: SC-02 | B6: C01 | C6: Approvals should be quick. | D6: THR-05 | E6: Vague quantity | F6: Yes | G6: What is the maximum time an approval may take? | H6: 4 business hours | I6: High | J6: Same day, ideally within 3 hours. | K6: THR-05 = 3 business hours | L6: Confirmed | M6: Medium | N6: Extracts the concrete value from a partly vague answer
A7: SC-03 | B7: C01 | C7: Orders should go to the nearest warehouse. | D7: RULE-21, RULE-22 | E7: Missing exception path | F7: Yes | G7: If the nearest warehouse is out of stock, should the order go to the next-nearest warehouse, wait for stock, or be split? | H7: No fallback (must set) | I7: High | J7: Send it to the Jaipur hub as backup. | K7: RULE-22 fallback = WH-Jaipur | L7: Confirmed | M7: Medium | N7: Detects a missing exception path
A8: SC-04 | B8: C01 | C8: Orders come from our ERP; accounts are in a separate package. | D8: INT-01 | E8: Missing integration detail | F8: Yes | G8: Which ERP version do you run, and which fields hold the order value and buyer code? | H8: API v3 standard mapping | I8: High | J8: Version 10; order value in 'ord_total', buyer code in 'cust_code'. | K8: INT-01 mapping ord_total -> order.value, cust_code -> buyer_code | L8: Confirmed | M8: Medium | N8: Integration detail needed for C3
A9: SC-05 | B9: C02 | C9: Dispatch within 2 days. | D9: THR-09, ADM-01 | E9: Vague quantity | F9: Yes | G9: Is that 48 clock hours or 2 working days? Which days are non-working? | H9: 24 business hours, Mon-Sat | I9: High | J9: 2 working days, Sundays off. | K9: THR-09 = 48 business hours; ADM-01 = Mon-Sat | L9: Confirmed | M9: Medium | N9: Unit and calendar ambiguity
A10: SC-06 | B10: C02 | C10: Escalate delayed orders to the ops head. | D10: RULE-31, THR-10 | E10: Vague quantity | F10: Yes | G10: How many hours past the dispatch deadline counts as delayed? | H10: 6 hours | I10: Medium | J10: The default is fine. | K10: THR-10 = 6 hours (template default confirmed); escalation role = ops_head | L10: Confirmed | M10: Easy | N10: Default offered and confirmed
A11: SC-07 | B11: C02 | C11: Heavy items go by freight. | D11: THR-11, RULE-32 | E11: Vague quantity | F11: Yes | G11: Above what weight should an order go by freight carrier? | H11: 100 kg | I11: High | J11: Anything over 40 kg, our planters are bulky. | K11: THR-11 = 40 kg | L11: Confirmed | M11: Medium | N11: Template default would be wrong for this customer
A12: SC-08 | B12: C02 | C12: (No mention of credit terms in notes.) | D12: THR-01, RULE-02 | E12: Not mentioned | F12: Yes | G12: Do you extend credit to any buyers? If not, we will switch off credit holds. | H12: Credit hold enabled, INR 10,00,000 | I12: Medium | J12: No, all orders are prepaid or COD. | K12: RULE-02 disabled | L12: Confirmed | M12: Medium | N12: Spots a template setting that does not apply
A13: SC-09 | B13: C03 | C13: Orders above INR 5 lakh need approval from the branch manager. | D13: THR-03, WF-02/S3 | E13: None (clear) | F13: No | G13: (no question) | K13: THR-03 = INR 5,00,000; S3 role = branch_manager (new role) | L13: Confirmed | M13: Easy | N13: Control: must NOT be flagged
A14: SC-10 | B14: C03 | C14: All orders from key accounts are auto-approved. | D14: RULE-12 (+ SC-09) | E14: Contradiction | F14: Yes | G14: Should key-account orders above INR 5 lakh skip branch manager approval, or does the INR 5 lakh rule still apply to them? | I14: High | J14: Key accounts skip approval up to INR 15 lakh; above that, branch manager. | K14: New RULE-12a: key accounts exempt up to INR 15,00,000 | L14: Confirmed | M14: Hard | N14: Contradiction across two notes
A15: SC-11 | B15: C03 | C15: We work with two courier partners and a freight partner. | D15: INT-03, RULE-32 | E15: Missing integration detail | F15: Yes | G15: Which partner should get which orders (by weight, zone or cost), and do all three support booking through an API? | H15: Courier by zone, freight > 100 kg | I15: High | J15: Courier A for metros, Courier B elsewhere, freight above 60 kg. Freight partner has no API, bookings by email. | K15: RULE-32 by zone + THR-11 = 60 kg; WF-05/S2 manual booking for freight | L15: Confirmed | M15: Hard | N15: Reveals an integration capability gap
A16: SC-12 | B16: C03 | C16: Peak is around Diwali. | D16: Capacity envelope (M7-M10) | E16: Missing volume info | F16: Yes | G16: What are your normal and peak daily order volumes, and which weeks are peak? | I16: High | J16: Normal about 1,200 a day; around 3,500 a day for three weeks at Diwali. | K16: Peak multiplier 2.9x; peak calendar = Diwali 3 weeks | L16: Confirmed | M16: Easy | N16: Collects inputs for load benchmark (A14)
A17: SC-13 | B17: C04 | C17: Client orders come in from multiple client ERPs. | D17: INT-01 (x n) | E17: Missing integration detail | F17: Yes | G17: How many client systems send orders, and does each use the same format or need its own mapping? | H17: Single API source | I17: High | J17: Four clients: two send CSV over SFTP, two use an API. | K17: INT-01 x 4; 2 via file transfer (needs platform eng. check) | L17: Confirmed - open dependency | M17: Hard | N17: Surfaces a dependency outside the template
A18: SC-14 | B18: C04 | C18: Each client has its own SLA. | D18: THR-09 (per client) | E18: Vague quantity | F18: Yes | G18: Please list the dispatch SLA for each client. | H18: 24 business hours | I18: High | J18: Client 1: 24h, Client 2: 24h, Client 3: 48h, Client 4: 72h. | K18: THR-09 per client = 24 / 24 / 48 / 72 | L18: Confirmed | M18: Medium | N18: One requirement maps to several values
A19: SC-15 | B19: C04 | C19: Exceptions go to the warehouse team. | D19: WF-04/S2 | E19: Missing owner | F19: Yes | G19: Who exactly owns the exception queue: a named role at each warehouse, or one central planner? | H19: warehouse_planner | I19: Medium | J19: The shift supervisor at each warehouse. | K19: WF-04/S2 role = shift_supervisor (per warehouse) | L19: Confirmed | M19: Medium | N19: Team named, owner role missing
A20: SC-16 | B20: C05 | C20: Same-day dispatch for all orders placed before 2 pm. | D20: THR-09, THR-13 | E20: None (clear) | F20: No | G20: (no question) | K20: THR-13 = 14:00; THR-09 = same business day | L20: Confirmed | M20: Easy | N20: Control: must NOT be flagged
A21: SC-17 | B21: C05 | C21: Returns should be handled smoothly. | D21: (none - out of scope) | E21: Out of scope | F21: Route to SE | G21: (no customer question; SE to clarify commercial scope) | I21: Medium | K21: Logged as out of scope (returns not in modules) | L21: Out of scope | M21: Medium | N21: Must not invent settings
A22: SC-18 | B22: C05 | C22: Generate GST invoices on dispatch. | D22: (Accounts - in ERP) | E22: Out of scope | F22: Route to SE | G22: (no customer question; SE to confirm invoice is created in ERP from dispatch event) | I22: Medium | K22: Out of scope; optional outbound dispatch event to ERP via integration | L22: Out of scope | M22: Hard | N22: Recognises Accounts is not a platform module
A23: SC-19 | B23: C06 | C23: Credit limit as per our existing policy. | D23: THR-01, RULE-02, WF-03 | E23: Vague quantity | F23: Yes | G23: Please share the credit policy: the limit for each buyer category and what happens when it is exceeded. | H23: INR 10,00,000 flat | I23: High | J23: Category A INR 10L, B INR 5L, C INR 2L; if exceeded, hold for the credit controller. | K23: THR-01 tiered A/B/C = 10L / 5L / 2L; RULE-02 -> WF-03 (credit_controller) | L23: Confirmed | M23: Medium | N23: Requirement points to an external document
A24: SC-20 | B24: C06 | C24: Approver: Mr. Rao. | D24: WF-02/S3, ADM-02 | E24: Missing owner | F24: Yes | G24: Who approves when Mr. Rao is unavailable? | I24: Medium | J24: Ms. Iyer is the backup. | K24: finance_approver role with 2 users (Rao, Iyer) | L24: Confirmed | M24: Medium | N24: Single-person dependency (links to H4)
A25: SC-21 | B25: C06 | C25: Dispatch SLA is 24 hours. | D25: THR-09 | E25: None (clear) | F25: No | G25: (no question) | K25: THR-09 = 24 business hours | L25: Confirmed | M25: Easy | N25: Control: must NOT be flagged
A26: SC-22 | B26: C07 | C26: Escalate if delayed beyond 4 hours. | D26: THR-10 | E26: None (clear) | F26: No | G26: (no question) | K26: THR-10 = 4 hours | L26: Confirmed | M26: Easy | N26: Control: must NOT be flagged
A27: SC-23 | B27: C07 | C27: Orders over INR 2 lakh need approval; orders over INR 1 lakh need approval from the finance head. | D27: THR-03, RULE-12, WF-02 | E27: Contradiction | F27: Yes | G27: For orders above INR 2 lakh, is it one approval (finance head) or two levels? Who approves orders between 1 and 2 lakh? | I27: High | J27: 1-2 lakh: branch manager. Above 2 lakh: finance head. | K27: Two-tier approval: INR 1-2L branch_manager; > INR 2L finance_head | L27: Confirmed | M27: Hard | N27: Overlapping, inverted thresholds
A28: SC-24 | B28: C07 | C28: Volumes go up in summer. | D28: Capacity envelope (M7-M10) | E28: Missing volume info | F28: Yes | G28: Round 1: What are normal and peak daily volumes, and which months? -> answer still vague -> Round 2: Roughly how many orders a day in summer vs the rest of the year? | I28: High | J28: Round 1: 'They go up a lot.' Round 2: 'About 700 normally, 1,400 in April-June.' | K28: Peak multiplier 2.0x; peak calendar = Apr-Jun | L28: Confirmed after round 2 | M28: Hard | N28: Must not accept a vague answer
A29: SC-25 | B29: C08 | C29: Integrate with our website orders. | D29: INT-01 | E29: Missing integration detail | F29: Yes | G29: Which platform runs your website, and does it offer an order API or webhooks? | H29: API v3 pull | I29: High | J29: A hosted store platform with webhooks. | K29: INT-01 webhook mode | L29: Confirmed | M29: Medium | N29: Order source is a web store, not an ERP
A30: SC-26 | B30: C08 | C30: Usual stuff for escalations. | D30: RULE-31, THR-10 | E30: Not mentioned | F30: Yes | G30: We will escalate to the dispatch lead 6 hours after the dispatch deadline. Is that right? | H30: 6 hours | I30: Low | J30: Yes. | K30: THR-10 = 6 hours (default confirmed) | L30: Confirmed | M30: Easy | N30: Low-impact item handled as a quick confirm
A31: SC-27 | B31: C08 | C31: Prepaid orders ship first. | D31: New rule (not in template) | E31: Needs custom rule | F31: Yes | G31: Should prepaid orders always be picked before COD orders, even when the COD order is older? | I31: Medium | J31: Yes, except COD orders older than 24 hours go first. | K31: New RULE-23: prepaid priority with 24h ageing override | L31: Confirmed | M31: Hard | N31: Requirement not covered by the template
A32: SC-28 | B32: C05 | C32: We promise next-day delivery in metros. | D32: THR-09, RULE-32 | E32: Vague quantity | F32: Yes | G32: Next-day delivery needs early dispatch. Should metro orders have a shorter dispatch SLA and an express courier? | H32: 24 business hours, standard courier | I32: High | J32: Metro orders: dispatch within 6 hours, express courier. | K32: Zone-specific THR-09 = 6h (metro); RULE-32 metro -> express courier | L32: Confirmed | M32: Hard | N32: Delivery promise implies dispatch settings

Sheet S2 Config Checks
A1: MVP · Sales · rule-based configuration checks (A4a / A5)
A2: Hard errors block the handoff to UAT. Warnings never block; they are listed for delivery. Deterministic: expected accuracy is 100%.
A4: Case | B4: Customer | C4: Setting | D4: Configured value (draft) | E4: Signed-off / required | F4: Check (R) | G4: Expected result | H4: Blocks handoff? | I4: Why
A5: CC-01 | B5: C01 | C5: THR-03 approval_limit | D5: INR 5,00,000 (template default) | E5: INR 8,00,000 (SC-01) | F5: SIGNOFF_MISMATCH | G5: Error | H5: Yes | I5: Value differs from signed-off requirement
A6: CC-02 | B6: C01 | C6: THR-05 approval_sla | D6: 3 business hours | E6: 3 business hours (SC-02) | F6: SIGNOFF_MISMATCH | G6: Pass | H6: No | I6: Matches sign-off
A7: CC-03 | B7: C01 | C7: RULE-22 stock_out_fallback | D7: (empty) | E7: WH-Jaipur (SC-03) | F7: REQUIRED_FIELD | G7: Error | H7: Yes | I7: Required field missing
A8: CC-04 | B8: C01 | C8: INT-01 field mapping | D8: buyer_code not mapped | E8: cust_code -> buyer_code (SC-04) | F8: REQUIRED_MAPPING | G8: Error | H8: Yes | I8: Mandatory mapping missing; would fail C3
A9: CC-05 | B9: C02 | C9: THR-11 bulky_weight | D9: 100 kg (template default) | E9: 40 kg (SC-07) | F9: SIGNOFF_MISMATCH | G9: Error | H9: Yes | I9: Template default left in place
A10: CC-06 | B10: C02 | C10: RULE-02 credit_hold | D10: enabled | E10: disabled (SC-08) | F10: SIGNOFF_MISMATCH | G10: Error | H10: Yes | I10: Rule should be off
A11: CC-07 | B11: C02 | C11: ADM-01 business_calendar | D11: Mon-Sun | E11: Mon-Sat (SC-05) | F11: SIGNOFF_MISMATCH | G11: Error | H11: Yes | I11: Calendar changes the SLA clock
A12: CC-08 | B12: C03 | C12: RULE-12 vs RULE-12a | D12: Both match key-account orders INR 5-15L, same priority, different actions | E12: RULE-12a exempts key accounts (SC-10) | F12: RULE_CONFLICT | G12: Error | H12: Yes | I12: Conflicting rules; would fail C2
A13: CC-09 | B13: C03 | C13: ADM-02 role branch_manager | D13: 0 active users in sandbox | E13: role required (SC-09) | F13: ROLE_EMPTY | G13: Warning | H13: No | I13: Users can be added before UAT; C4 will fail if not
A14: CC-10 | B14: C03 | C14: THR-11 bulky_weight | D14: 60 kg | E14: 60 kg (SC-11) | F14: SIGNOFF_MISMATCH | G14: Pass | H14: No | I14: Matches sign-off
A15: CC-11 | B15: C04 | C15: INT-01 (clients 1-2) endpoint | D15: API v2 | E15: API (SC-13) | F15: DEPRECATED_VERSION | G15: Warning | H15: No | I15: v2 deprecated but supported; template is v3
... A24: CC-20 | B24: C08 | C24: RULE-23 prepaid priority | D24: Never reached: RULE-21 has stop-processing set | E24: RULE-23 must fire (SC-27) | F24: UNREACHABLE_RULE | G24: Error | H24: Yes | I24: Rule can never fire; would fail C2

Sheet U1 UAT Diagnosis
A1: MVP · UAT · Diagnosis & Tuning Agent
A2: R narrows candidate settings via the dependency map · J ranks · L investigates events, tests fixes in the sandbox (A20), and proposes or escalates. Signed-off requirements are hard limits.
A4: Case | B4: Customer | C4: Failing metric | D4: Observed | E4: Target | F4: Evidence pattern in events (input) | G4: Candidate settings (R) | H4: True root cause | I4: Cause class | J4: Expected agent action | K4: Expected sandbox effect | L4: Must NOT do | M4: Difficulty
A5: UD-01 | B5: C09 | C5: M1 Approval cycle time | D5: 7.2 h | E5: <= 4 h | F5: 62% of test orders hit approval; steel orders are mostly INR 3-6L; one finance_approver handles all of them | G5: THR-03, THR-05, WF-02/S3 users | H5: Signed-off approval_limit (INR 2L) sends most orders to one approver | I5: Requirement conflicts with target | J5: Escalate options to customer via delivery: (a) raise limit to INR 5L, (b) add a second approver | K5: (a) approvals 18% of orders, M1 3.1 h; (b) M1 3.8 h | L5: Change approval_limit without customer decision | M5: Hard
A6: UD-02 | B6: C09 | C6: M2 Auto-routing accuracy | D6: 88% | E6: >= 95% | F6: 80% of manual reassignments are pincodes 208xxx moved from WH-1 to WH-2 | G6: RULE-21 (state rule, pincode rule), INT-02 | H6: General state rule has higher priority than the specific pincode rule | I6: Configuration error | J6: Propose priority swap (specific before general) | K6: M2 97%, M3 3.1%, no other metric worse | M6: Medium
A7: UD-03 | B7: C10 | C7: M4 On-time dispatch | D7: 88% | E7: >= 95% | F7: Late orders are almost all > 40 kg; freight carrier collects twice a week; sign-off says 24h dispatch for all orders | G7: THR-09, THR-11, RULE-32, WF-05 | H7: Signed-off 24h SLA cannot be met for bulky items with current freight collection | I7: Requirement conflicts with target | J7: Draft options for customer: (a) 72h SLA for bulky, (b) daily freight collection, (c) separate M4 target for bulky | K7: (a) M4 97%; (b) depends on carrier contract; (c) M4 standard 98% | L7: Silently change the SLA | M7: Hard
A8: UD-04 | B8: C10 | C8: M6 Integration sync success | D8: 96.5% | E8: >= 99% | F8: Failures cluster 02:00-03:00 daily; carrier returns maintenance errors; retries 3 x 1 min | G8: INT-03 retry policy, INT-03 sync frequency | H8: Retry window too short for the carrier's nightly maintenance | I8: Configuration error | J8: Propose back-off retries up to 90 min and queue bookings in the window | K8: M6 99.6% | M8: Medium
A9: UD-05 | B9: C11 | C9: M3 Manual override rate | D9: 9% | E9: <= 5% | F9: Overrides are users changing the carrier for Northeast pincodes; Courier A returns 'not serviceable' | G9: RULE-32 zone map, INT-03 | H9: Carrier zone map sends Northeast orders to a courier that does not serve them | I9: Configuration error | J9: Propose Northeast zone -> Courier B | K9: M3 4.2%, M4 +1.5 pts | M9: Medium
A10: UD-06 | B10: C11 | C10: M5 Escalation rate | D10: 7% | E10: <= 3% | F10: Escalations fire mainly for orders created after 16:00; escalation threshold is 2h | G10: RULE-31, THR-10, THR-13 | H10: Two causes: RULE-31 starts the clock at order creation, not the next business slot (primary); THR-10 = 2h with no linked requirement (secondary) | I10: Configuration error (two causes) | J10: Propose RULE-31 fix; ask SE whether 2h was a customer request before changing THR-10 | K10: RULE-31 fix: 3.6%; plus THR-10 = 6h: 2.1% | L10: Change THR-10 without checking its origin | M10: Hard
A11: UD-07 | B11: C12 | C11: M9 Integration load | D11: 412 rate-limit errors at peak test | E11: Zero | F11: Carrier booking is called once per order; peak test reaches ~1,900 calls/hr vs limit 600 | G11: INT-03 booking mode, INT-03 sync frequency | H11: Per-order booking calls exceed the carrier's rate limit at peak | I11: Configuration error | J11: Propose batched booking every 5 min | K11: Zero rate-limit errors at 3x peak | M11: Medium
A12: UD-08 | B12: C12 | C12: M10 Workflow capacity | D12: Exception queue 4x planner capacity at peak | E12: Within SLA | F12: 70% of exceptions are allocation timeouts; warehouse system p95 response rises to 40 min at peak | G12: THR-07, WF-04/S2 users, INT-02 | H12: Allocation timeout (30 min) too short at peak, pushing orders into the exception queue | I12: Configuration error (capacity) | J12: Propose THR-07 = 60 min; flag planner capacity to delivery | K12: Exceptions -65% at peak; queue within SLA | M12: Hard
A13: UD-09 | B13: C13 | C13: M1 Approval cycle time | D13: 11 h | E13: <= 4 h | F13: All test approvals were raised in one batch on Friday 18:00; business calendar excludes Sunday | G13: THR-03, THR-05, ADM-01 | H13: Test data artefact: unrealistic timestamps, not a configuration problem | I13: Test data issue | J13: Flag test data; recommend re-run with realistic timestamps; no configuration change | K13: (none) | L13: Propose any configuration change | M13: Hard
A14: UD-10 | B14: C13 | C14: C3 Integration data accuracy | D14: 96% match on sample | E14: 100% | F14: Mismatched orders differ by exactly the tax amount | G14: INT-01 field mapping | H14: Mapping uses the tax-inclusive total; Vertex Ops expects the pre-tax value | I14: Configuration error | J14: Propose mapping net_total -> order.value | K14: 100% match on sample | M14: Easy
A15: UD-11 | B15: C09 | C15: C4 Role completeness | D15: credit_controller has 0 users | E15: 100% | F15: Rule check already identifies the empty role | G15: ADM-02 | H15: Admin setup incomplete | I15: Rule-only (no AI needed) | J15: Rule routes to delivery to add a user; agent is not invoked | K15: (n/a) | L15: Invoke AI diagnosis | M15: Easy
A16: UD-12 | B16: C12 | C16: M4 On-time dispatch | D16: 93% (was 97% before last change) | E16: >= 95% | F16: Drop started right after UD-07 fix; late orders are those booked in the last 5 min before cutoff | G16: INT-03 batch interval (recent change), THR-13 | H16: Regression from the batching change: bookings for late orders miss the cutoff | I16: Regression from recent change | J16: Propose batch interval 2 min (stays under 600 calls/hr) | K16: M4 97%, M9 still zero errors | M16: Hard

Sheet P1 Safety Net (MVP)
A1: MVP · Production · rule-based safety net
A2: Only hard failures (H1, H3, H4) with no ambiguity. Tickets created in the existing support tool; duplicates merged; unacknowledged P1s re-escalate after 1 hour.
A4: Case | B4: Customer | C4: Signal observed (input) | D4: Check | E4: Expected alert? | F4: Severity | G4: Routed to | H4: Why
A5: PS-01 | B5: C14 | C5: Carrier sync success 91% over the last hour | D5: H1 | E5: Yes | F5: P1 | G5: Support -> Platform eng. | H5: Below 95%
A6: PS-02 | B6: C15 | C6: Carrier sync success 96% over the last hour | D6: H1 | E6: No | H6: Near miss: above 95%
A7: PS-03 | B7: C16 | C7: ERP authentication errors for 20 min (expired credential) | D7: H1 | E7: Yes | F7: P1 | G7: CSM -> customer IT | H7: Customer-side cause
A8: PS-04 | B8: C17 | C8: 14 orders in approval step for 9 h (SLA 4 h) | D8: H3 | E8: Yes | F8: P2 | G8: CSM -> customer admin | H8: More than 2x SLA
A9: PS-05 | B9: C18 | C9: Orders in dispatch step for 40 h (SLA 24 h) | D9: H3 | E9: No | H9: Near miss: 1.7x SLA
A10: PS-06 | B10: C19 | C10: Only finance_approver user deactivated | D10: H4 | E10: Yes | F10: P1 | G10: CSM -> customer admin | H10: Role has no active user
A11: PS-07 | B11: C20 | C11: Approver on leave but account still active | D11: H4 | E11: No | H11: Known limitation: leave not visible to the rule
A12: PS-08 | B12: C14 | C12: Sync fails for 20 min then recovers; 1-hour success 97% | D12: H1 | E12: No | H12: Window-based rule avoids noise
A13: PS-09 | B13: C21 | C13: H1 P1 ticket unacknowledged for 1 hour | D13: Escalation | E13: Yes (re-escalate) | F13: P1 | G13: Platform eng. lead | H13: Response time passed
A14: PS-10 | B14: C15 | C14: H3 condition true on 3 steps of the same account | D14: H3 (dedupe) | E14: Yes (1 ticket) | F14: P2 | G14: CSM -> customer admin | H14: One ticket per issue per account

Sheet P2 Drift (V2)
A1: V2 · Production · Level 2 fit monitoring
A2: R compares weekly values with the go-live baseline (peak calendar excluded) · J decides real drift vs noise · L investigates and drafts a fix · CSM approves.
A4: Case | B4: Customer | C4: Metric | D4: Unit | E4: Go-live baseline | F4: W1 | G4: W2 | H4: W3 | I4: W4 | J4: W5 | K4: W6 | L4: W7 | M4: W8 | N4: Change W8 vs baseline | O4: Context (input) | P4: Expected classification | Q4: Cause | R4: Expected action | S4: Difficulty
A5: PD-01 | B5: C14 | C5: M1 Approval cycle time | D5: hours | E5: 3.5 | F5: 3.6 | G5: 3.8 | H5: 4.4 | I5: 5.2 | J5: 6.1 | K5: 7 | L5: 8.2 | M5: 9 | N5: =M5-E5 -> 5.5 | O5: Order volume doubled; RULE-12 fires on 40% of orders (was 12%) | P5: Real drift | Q5: approval_limit no longer fits volume | R5: Propose THR-03 INR 5L -> 8L; expected approvals -30% | S5: Medium
A6: PD-02 | B6: C15 | C6: M4 On-time dispatch | D6: % | E6: 96 | F6: 96 | G6: 95 | H6: 96 | I6: 89 | J6: 87 | K6: 90 | L6: 95 | M6: 96 | N6: =M6-E6 -> 0 | O6: Weeks 4-6 fall in the Diwali window in the peak calendar | P6: Noise (known peak) | Q6: Seasonal surge | R6: No drift alert; note for next year's peak-mode plan | S6: Hard
A7: PD-03 | B7: C16 | C7: M2 Auto-routing accuracy | D7: % | E7: 97 | F7: 97 | G7: 96 | H7: 96 | I7: 91 | J7: 90 | K7: 89 | L7: 89 | M7: 88 | N7: =M7-E7 -> -9 | O7: New warehouse WH-4 (Nagpur) appears in manual reassignments from week 4 | P7: Real drift | Q7: Routing rules do not include the new warehouse | R7: Propose RULE-21 regions for WH-4 | S7: Medium
A8: PD-04 | B8: C17 | C8: M6 Integration sync success | D8: % | E8: 99.5 | F8: 99.5 | G8: 99.4 | H8: 97.1 | I8: 96.8 | J8: 96.9 | K8: 97 | L8: 96.7 | M8: 96.8 | N8: =M8-E8 -> -2.7 | O8: Step change after carrier API version notice; H1 never fires (stays above 95%) | P8: Real drift | Q8: Carrier endpoint version outdated | R8: Propose INT-03 endpoint update | S8: Medium
A9: PD-05 | B9: C18 | C9: M3 Manual override rate | D9: % | E9: 3 | F9: 3 | G9: 3.4 | H9: 3.9 | I9: 4.5 | J9: 5.2 | K9: 6 | L9: 6.8 | M9: 7.5 | N9: =M9-E9 -> 4.5 | O9: Overrides concentrated on a new bulky sofa category | P9: Real drift (gradual) | Q9: Carrier and SLA rules do not fit the new category | R9: Propose category-specific THR-11 / RULE-32 | S9: Hard
A10: PD-06 | B10: C19 | C10: M8 Order throughput | D10: x tested envelope | E10: 1 | F10: 1 | G10: 1.1 | H10: 1.2 | I10: 1.3 | J10: 1.3 | K10: 1.4 | L10: 1.4 | M10: 1.4 | N10: =M10-E10 -> 0.4 | O10: Above the tested envelope for 16 days, outside any known peak | P10: Sustained growth | Q10: Business has grown | R10: Re-benchmark + Level 2 review of volume-linked settings; update baseline with approval | S10: Hard
A11: PD-07 | B11: C20 | C11: M1 Approval cycle time | D11: hours | E11: 3.2 | F11: 3.1 | G11: 3.3 | H11: 3.2 | I11: 3.4 | J11: 3.1 | K11: 3.2 | L11: 3.3 | M11: 3.2 | N11: =M11-E11 -> 0 | O11: Single-day spike to 12 h on month-end, weekly median unaffected | P11: Noise (month-end) | Q11: Month-end batch | R11: No action | S11: Medium
A12: PD-08 | B12: C21 | C12: M5 Escalation rate | D12: % | E12: 2 | F12: 2 | G12: 2.1 | H12: 1.9 | I12: 2.2 | J12: 4.8 | K12: 5.1 | L12: 5 | M12: 5.3 | N12: =M12-E12 -> 3.3 | O12: dispatch_lead role reassigned to one person covering two warehouses from week 5 | P12: Real drift | Q12: Workflow capacity: one dispatch lead for two sites | R12: Propose adding a dispatch_lead user per warehouse | S12: Medium

Sheet Evaluation
A1: How each sheet is scored: proposed launch gates
A2: Gates are our proposal for go/no-go before each phase; they are re-run on every prompt or model change (regression evaluation).
A4: Sheet | B4: Layer | C4: Measure | D4: How it is scored | E4: Proposed gate | F4: Gate applies at
A5: S1 Clarification | B5: L | C5: Ambiguity recall | D5: Flagged cases / cases that should be flagged | E5: >= 90% | F5: MVP launch
A6: S1 Clarification | B6: L | C6: False flags on controls | D6: Controls flagged / all controls | E6: <= 10% | F6: MVP launch
A7: S1 Clarification | B7: L | C7: Question quality | D7: Rubric 1-5: specific, linked to a setting, offers default, one gap per question | E7: Average >= 4 | F7: MVP launch
A8: S1 Clarification | B8: L | C8: Invented requirements | D8: Requirements without a source quote or customer answer | E8: Zero (hard gate) | F8: MVP launch
A9: S1 Clarification | B9: L | C9: Out-of-scope handling / vague answers | D9: Out-of-scope routed to SE; vague answers trigger another round | E9: 100% | F9: MVP launch
A10: S2 Config Checks | B10: R | C10: Rule accuracy | D10: Expected result matched (Error / Warning / Pass) and correct block decision | E10: 100% (unit tests) | F10: MVP launch
A11: U1 UAT Diagnosis | B11: R+J+L | C11: Root cause in top 3 | D11: True root cause appears in the agent's top-3 hypotheses | E11: >= 80% | F11: MVP launch
A12: U1 UAT Diagnosis | B12: L | C12: Cause class correct | D12: Config error vs requirement conflict vs test data vs regression | E12: >= 85% | F12: MVP launch
A13: U1 UAT Diagnosis | B13: L | C13: Sign-off violations | D13: Proposals that break a signed-off requirement | E13: Zero (hard gate) | F13: MVP launch
A14: U1 UAT Diagnosis | B14: L | C14: Correct 'no change' | D14: Test-data and rule-only cases receive no configuration proposal | E14: 100% | F14: MVP launch
A15: U1 UAT Diagnosis | B15: L | C15: Sandbox prediction accuracy | D15: Predicted vs actual metric on UAT re-run | E15: Within +/- 2 pts | F15: Tracked from MVP
... A21: All agent sheets | B21: H | C21: Human acceptance (post-launch) | D21: Accepted / edited / rejected proposals; rejections become new golden cases | E21: Monitored | F21: After launch

Sheet Assumptions
A1: Assumption register
A2: Referenced by number throughout the submission.
A4: # | B4: Area | C4: Assumption
A5: A0 | B5: Domain | C5: Vertex Ops serves mid-market Indian companies running order-to-delivery operations (distributors, D2C brands, 3PLs). Base schema, Copilot design and governance are domain-neutral; only the template, metric library and examples are logistics-specific.
A6: A1 | B6: Schema | C6: Separate sandbox, UAT and production environments exist.
A7: A2 | B7: Schema | C7: Configurations are versioned, but the reason for each change is not recorded.
A8: A3 | B8: Schema | C8: Execution events (rule fired, step completed, integration sync, manual override) are logged and available through an API.
A9: A4 | B9: Schema | C9: Metric definitions live in the UAT tool, not the configuration engine.
A10: A5 | B10: Constraint | C10: The Copilot reads configurations and proposes changes; live changes go through existing approvals.
A11: A6 | B11: As-is gap | C11: Configuration starts after the deal is signed.
A12: A7 | B12: As-is gap | C12: Handoff notes are written by sales and the SE together.
A13: A8 | B13: As-is gap | C13: Production changes are approved by platform engineering through the existing change-approval process.
A14: A9 | B14: As-is gap | C14: Production issues are investigated by delivery's configuration specialists after CS escalates.
A15: A10 | B15: As-is gap | C15: Go-live metric targets are not carried into production today.
... A25: A20 | B25: Schema | C25: The engine can clone a configuration version into the sandbox and replay recorded UAT scenarios via API. Fallback: reasoned proposals, tested by delivery in UAT.
